Workbook

Sheet yazlık
A1: AYLAR | B1: REKOLTE (KG) | C1: MALİYET (TL) | D1: SATIŞ (TL) | E1: KAR/ZARAR (TL) | F1: DOMATES FİYAT | H1: SERA ALANINA GÖRE (TL/m2)
F2: TL/KG | G2: USD/KG | H2: GELİR (TL/m2) | I2: GİDER(TL/m2) | J2: KAR/ZARAR(TL/m2)
A3: Ocak | B3: =H65*B35 -> 0 | C3: =J21 -> 1747580.4 | D3: =B3*F3 -> 0 | E3: =D3-C3 -> -1747580.4 | F3: 55 | G3: =F3/C36 -> 1.3924051 | H3: =D3/G41 -> 0 | I3: =C3/G41 -> 87.379019 | J3: =H3-I3 -> -87.379019
A4: Şubat | B4: =H66*B35 -> 0 | C4: =J22 -> 1796692.9 | D4: =B4*F4 -> 0 | E4: =D4-C4 -> -1796692.9 | F4: 55 | G4: =F4/C36 -> 1.3924051 | H4: =D4/G41 -> 0 | I4: =C4/G41 -> 89.834643 | J4: =H4-I4 -> -89.834643
A5: Mart | B5: =H67*B35 -> 20000 | C5: =J23 -> 1562795.3 | D5: =B5*F5 -> 1100000 | E5: =D5-C5 -> -462795.31 | F5: 55 | G5: =F5/C36 -> 1.3924051 | H5: =D5/G41 -> 55 | I5: =C5/G41 -> 78.139766 | J5: =H5-I5 -> -23.139766
A6: Nisan | B6: =H68*B35 -> 80000 | C6: =J24 -> 1410622 | D6: =B6*F6 -> 4000000 | E6: =D6-C6 -> 2589378 | F6: 50 | G6: =F6/C36 -> 1.2658228 | H6: =D6/G41 -> 200 | I6: =C6/G41 -> 70.5311 | J6: =H6-I6 -> 129.4689
A7: Mayıs | B7: =H69*B35 -> 120000 | C7: =J25 -> 1446914.2 | D7: =B7*F7 -> 3000000 | E7: =D7-C7 -> 1553085.8 | F7: 25 | G7: =F7/C36 -> 0.63291139 | H7: =D7/G41 -> 150 | I7: =C7/G41 -> 72.34571 | J7: =H7-I7 -> 77.65429
A8: Haziran | B8: =H70*B35 -> 180000 | C8: =J26 -> 1906869.5 | D8: =B8*F8 -> 4500000 | E8: =D8-C8 -> 2593130.5 | F8: 25 | G8: =F8/C36 -> 0.63291139 | H8: =D8/G41 -> 225 | I8: =C8/G41 -> 95.343474 | J8: =H8-I8 -> 129.65653
A9: Temmuz | B9: =H71*B35 -> 220000 | C9: =J27 -> 2399019.8 | D9: =B9*F9 -> 5500000 | E9: =D9-C9 -> 3100980.2 | F9: 25 | G9: =F9/C36 -> 0.63291139 | H9: =D9/G41 -> 275 | I9: =C9/G41 -> 119.95099 | J9: =H9-I9 -> 155.04901
A10: Ağustos | B10: =H72*B35 -> 220000 | C10: =J28 -> 2134561.2 | D10: =B10*F10 -> 5500000 | E10: =D10-C10 -> 3365438.8 | F10: 25 | G10: =F10/C36 -> 0.63291139 | H10: =D10/G41 -> 275 | I10: =C10/G41 -> 106.72806 | J10: =H10-I10 -> 168.27194
A11: Eylül | B11: =H73*B35 -> 120000 | C11: =J29 -> 1426891.5 | D11: =B11*F11 -> 3600000 | E11: =D11-C11 -> 2173108.5 | F11: 30 | G11: =F11/C36 -> 0.75949367 | H11: =D11/G41 -> 180 | I11: =C11/G41 -> 71.344574 | J11: =H11-I11 -> 108.65543
A12: Ekim | B12: =H74*B35 -> 100000 | C12: =J30 -> 1180578.7 | D12: =B12*F12 -> 3500000 | E12: =D12-C12 -> 2319421.3 | F12: 35 | G12: =F12/C36 -> 0.88607595 | H12: =D12/G41 -> 175 | I12: =C12/G41 -> 59.028934 | J12: =H12-I12 -> 115.97107
A13: Kasım | B13: =H75*B35 -> 80000 | C13: =J31 -> 2828545 | D13: =B13*F13 -> 3200000 | E13: =D13-C13 -> 371454.96 | F13: 40 | G13: =F13/C36 -> 1.0126582 | H13: =D13/G41 -> 160 | I13: =C13/G41 -> 141.42725 | J13: =H13-I13 -> 18.572748
A14: Aralık | B14: =H76*B35 -> 0 | C14: =J32 -> 1953300.2 | D14: =B14*F14 -> 0 | E14: =D14-C14 -> -1953300.2 | F14: ='[1]kışlık desen'!F14 -> 50 | G14: =F14/C36 -> 1.2658228 | H14: =D14/G41 -> 0 | I14: =C14/G41 -> 97.66501 | J14: =H14-I14 -> -97.66501
A15: TOPLAM | B15: =SUM(B3:B14) -> 1140000 | C15: =SUM(C3:C14) -> 21794371 | D15: =SUM(D3:D14) -> 33900000 | E15: =SUM(E3:E14) -> 12105629 | F15: =D15/B15 -> 29.736842 | G15: =F15/C36 -> 0.75283145 | H15: =D15/G41 -> 1695 | I15: =C15/G41 -> 1089.7185 | J15: =H15-I15 -> 605.28147
A16: usd/m2 | C16: =C15/C36 -> 551756.22 | D16: =D15/C36 -> 858227.85 | E16: =E15/C36 -> 306471.63
A17: usd/m2 | H17: =H15/C36 -> 42.911392 | I17: =I15/C36 -> 27.587811 | J17: =J15/C36 -> 15.323581
A19: AYLAR | B19: HAMMADDE GİDERLERİ (TL) | F19: ENERJİ GİDERLERİ (TL) | G19: PERSONEL GİDERLERİ (TL) | H19: AMBALAJ GİDERLERİ (TL) | I19: G.Ü.G (TL) | J19: TOPLAM GİDER (TL)
B20: GÜBRE | C20: TOHUM/FİDE | D20: ÜRETİM ORTAMI | E20: İLAÇ
A21: OCAK | B21: =D104*B35 -> 29560 | E21: =B35*D38*C36 -> 0 | F21: =(B35*B47*5)+D47*B35 -> 1040000 | G21: =H88+I88 -> 577300.2 | H21: =C62*B35 -> 0 | I21: =(E125+F125+H125+K125+G47+J47)/20000*B35 -> 100720.18 | J21: =SUM(B21:I21) -> 1747580.4
A22: ŞUBAT | B22: =D105*B35 -> 29560 | F22: =B35*B48*5+D48*B35 -> 1040000 | G22: =H89+I89 -> 577300.2 | H22: =C63*B35 -> 0 | I22: =(E126+F126+H126+K126+G48+J48)/20000*B35 -> 149832.66 | J22: =SUM(B22:I22) -> 1796692.9
A23: MART | B23: =D106*B35 -> 73900 | E23: =B35*(B38/4)*C36 -> 98750 | F23: =B35*B49*5+D49*B35 -> 672857.14 | G23: =H90+I90 -> 577300.2 | H23: =C64*B35 -> 60000 | I23: =(E127+F127+H127+K127+G49+J49)/20000*B35 -> 79987.97 | J23: =SUM(B23:I23) -> 1562795.3
A24: NİSAN | B24: =D107*B35 -> 147800 | E24: =E23 -> 98750 | F24: =B35*B50*5+D50*B35 -> 297142.86 | G24: =H91+I91 -> 577300.2 | H24: =C65*B35 -> 240000 | I24: =(E128+F128+H128+K128+G50+J50)/20000*B35 -> 49628.95 | J24: =SUM(B24:I24) -> 1410622
A25: MAYIS | B25: =D108*B35 -> 221700 | E25: =E21 -> 0 | F25: =B35*B51*5+D51*B35 -> 170771.43 | G25: =H92+I92 -> 577300.2 | H25: =C66*B35 -> 360000 | I25: =(E129+F129+H129+K129+G51+J51)/20000*B35 -> 117142.58 | J25: =SUM(B25:I25) -> 1446914.2
A26: HAZİRAN | B26: =D109*B35 -> 369500 | F26: =B35*B52*5+D52*B35 -> 53214.286 | G26: =H93+I93 -> 865948.2 | H26: =C67*B35 -> 540000 | I26: =(E130+F130+H130+K130+G52+J52)/20000*B35 -> 78207 | J26: =SUM(B26:I26) -> 1906869.5
A27: TEMMUZ | B27: =D110*B35 -> 443400 | E27: =E23 -> 98750 | F27: =B35*B53*5+D53*B35 -> 52914.286 | G27: =H94+I94 -> 865948.2 | H27: =C68*B35 -> 660000 | I27: =(E131+F131+H131+K131+G53+J53)/20000*B35 -> 278007.28 | J27: =SUM(B27:I27) -> 2399019.8
A28: AĞUSTOS | B28: =D111*B35 -> 443400 | F28: =B35*B54*5+D54*B35 -> 50000 | G28: =H95+I95 -> 865948.2 | H28: =C69*B35 -> 660000 | I28: =(E132+F132+H132+K132+G54+J54)/20000*B35 -> 115213 | J28: =SUM(B28:I28) -> 2134561.2
A29: EYLÜL | B29: =D112*B35 -> 147800 | E29: =E23 -> 98750 | F29: =B35*B55*5+D55*B35 -> 65114.286 | G29: =H96+I96 -> 721624.2 | H29: =C70*B35 -> 360000 | I29: =(E133+F133+H133+K133+G55+J55)/20000*B35 -> 33603 | J29: =SUM(B29:I29) -> 1426891.5
A30: EKİM | B30: =D113*B35 -> 73900 | F30: =B35*B56*5+D56*B35 -> 182857.14 | G30: =H97+I97 -> 577300.2 | H30: =C71*B35 -> 300000 | I30: =(E134+F134+H134+K134+G56+J56)/20000*B35 -> 46521.33 | J30: =SUM(B30:I30) -> 1180578.7
A31: KASIM | B31: =D114*B35 -> 44340 | C31: =B35*B40*E40 -> 576000 | D31: =B35*C39*C36*0.6 -> 829500 | F31: =B35*B57*5+D57*B35 -> 545000 | G31: =H98+I98 -> 577300.2 | H31: =C72*B35 -> 240000 | I31: =(E135+F135+H135+K135+G57+J57)/20000*B35 -> 16404.84 | J31: =SUM(B31:I31) -> 2828545
A32: ARALIK* | B32: =D115*B35 -> 0 | C32: =B35*B40*G40 -> 576000 | F32: =B35*B58*5+D58*B35 -> 800000 | G32: =H99+I99 -> 577300.2 | H32: =C73*B35 -> 0 | I32: =(E136+F136+H136+K136+G58+J58)/20000*B35 -> 0 | J32: =SUM(B32:I32) -> 1953300.2
A33: TOPLAM | B33: =SUM(B21:B32) -> 2024860 | C33: =SUM(C21:C32) -> 1152000 | D33: =SUM(D21:D32) -> 829500 | E33: =SUM(E21:E32) -> 395000 | F33: =SUM(F21:F32) -> 4969871.4 | G33: =SUM(G21:G32) -> 7937870.4 | H33: =SUM(H21:H32) -> 3420000 | I33: =SUM(I21:I32) -> 1065268.8 | J33: =SUM(B33:I33) -> 21794371
A34: toplam usd/m2 | B34: =B33/C36 -> 51262.278 | C34: =C33/C36 -> 29164.557 | D34: =D33/C36 -> 21000 | E34: =E33/C36 -> 10000 | F34: =F33/C36 -> 125819.53 | G34: =G33/C36 -> 200958.74 | H34: =H33/C36 -> 86582.278 | I34: =I33/C36 -> 26968.83 | J34: =J33/C36 -> 551756.22
A35: sera alanı m2 | B35: 20000
A36: usd/tl | C36: 39.5
A37: Gübre | B37: =B33/B35 -> 101.243
A38: İlaç | B38: 0.5 | C38: usd/m2 | D38: 0 | E38: usd/m2 | F38: toplam ilaç | G38: =B38+D38+J38 -> 0.76 | H38: usd/m2 | I38: stopmate usd/m2 | J38: 0.26
A39: Üretim ort. Cocopeat | C39: 1.75 | D39: usd/adet
A40: tohum/fide | B40: 3.6 | C40: bitki/m2 | D40: tohum tl/ad | E40: 8 | F40: fide tl/adet | G40: 8
A41: işçilik | B41: =J86 -> 432.972 | C41: tl/m2 | E41: sera alanı m2 | G41: =B35 -> 20000
...

Sheet ara dikim
A1: AYLAR | B1: REKOLTE (KG) | C1: MALİYET (TL) | D1: SATIŞ (TL) | E1: KAR/ZARAR (TL) | F1: DOMATES FİYAT | H1: SERA ALANINA GÖRE (TL/m2)
F2: TL/KG | G2: USD/KG | H2: GELİR (TL/m2) | I2: GİDER(TL/m2) | J2: KAR/ZARAR(TL/m2)
A3: Ocak | B3: =H65*B35 -> 0 | C3: =J21 -> 334246.2 | D3: =B3*F3 -> 0 | E3: =D3-C3 -> -334246.2 | F3: 50 | G3: =F3/C36 -> 1.2658228 | H3: =D3/G41 -> 0 | I3: =C3/G41 -> 16.71231 | J3: =H3-I3 -> -16.71231
A4: Şubat | B4: =H66*B35 -> 0 | C4: =J22 -> 334246.2 | D4: =B4*F4 -> 0 | E4: =D4-C4 -> -334246.2 | F4: ='[1]kışlık desen'!F4 -> 50 | G4: =F4/C36 -> 1.2658228 | H4: =D4/G41 -> 0 | I4: =C4/G41 -> 16.71231 | J4: =H4-I4 -> -16.71231
A5: Mart | B5: =H67*B35 -> 0 | C5: =J23 -> 1236549.3 | D5: =B5*F5 -> 0 | E5: =D5-C5 -> -1236549.3 | F5: ='[1]kışlık desen'!F5 -> 60 | G5: =F5/C36 -> 1.5189873 | H5: =D5/G41 -> 0 | I5: =C5/G41 -> 61.827466 | J5: =H5-I5 -> -61.827466
A6: Nisan | B6: =H68*B35 -> 0 | C6: =J24 -> 1005436 | D6: =B6*F6 -> 0 | E6: =D6-C6 -> -1005436 | F6: ='[1]kışlık desen'!F6 -> 45 | G6: =F6/C36 -> 1.1392405 | H6: =D6/G41 -> 0 | I6: =C6/G41 -> 50.2718 | J6: =H6-I6 -> -50.2718
A7: Mayıs | B7: =H69*B35 -> 20000 | C7: =J25 -> 1266785.7 | D7: =B7*F7 -> 500000 | E7: =D7-C7 -> -766785.74 | F7: ='[1]kışlık desen'!F7 -> 25 | G7: =F7/C36 -> 0.63291139 | H7: =D7/G41 -> 25 | I7: =C7/G41 -> 63.339287 | J7: =H7-I7 -> -38.339287
A8: Haziran | B8: =H70*B35 -> 120000 | C8: =J26 -> 1614498.5 | D8: =B8*F8 -> 3000000 | E8: =D8-C8 -> 1385501.5 | F8: 25 | G8: =F8/C36 -> 0.63291139 | H8: =D8/G41 -> 150 | I8: =C8/G41 -> 80.724924 | J8: =H8-I8 -> 69.275076
A9: Temmuz | B9: =H71*B35 -> 200000 | C9: =J27 -> 2332779.8 | D9: =B9*F9 -> 5000000 | E9: =D9-C9 -> 2667220.2 | F9: 25 | G9: =F9/C36 -> 0.63291139 | H9: =D9/G41 -> 250 | I9: =C9/G41 -> 116.63899 | J9: =H9-I9 -> 133.36101
A10: Ağustos | B10: =H72*B35 -> 200000 | C10: =J28 -> 2106725.5 | D10: =B10*F10 -> 5000000 | E10: =D10-C10 -> 2893274.5 | F10: ='[1]kışlık desen'!F10 -> 25 | G10: =F10/C36 -> 0.63291139 | H10: =D10/G41 -> 250 | I10: =C10/G41 -> 105.33628 | J10: =H10-I10 -> 144.66372
A11: Eylül | B11: =H73*B35 -> 120000 | C11: =J29 -> 1437291.5 | D11: =B11*F11 -> 3600000 | E11: =D11-C11 -> 2162708.5 | F11: ='[1]kışlık desen'!F11 -> 30 | G11: =F11/C36 -> 0.75949367 | H11: =D11/G41 -> 180 | I11: =C11/G41 -> 71.864574 | J11: =H11-I11 -> 108.13543
A12: Ekim | B12: =H74*B35 -> 120000 | C12: =J30 -> 1400502.7 | D12: =B12*F12 -> 4800000 | E12: =D12-C12 -> 3399497.3 | F12: ='[1]kışlık desen'!F12 -> 40 | G12: =F12/C36 -> 1.0126582 | H12: =D12/G41 -> 240 | I12: =C12/G41 -> 70.025134 | J12: =H12-I12 -> 169.97487
A13: Kasım | B13: =H75*B35 -> 100000 | C13: =J31 -> 2783565 | D13: =B13*F13 -> 5000000 | E13: =D13-C13 -> 2216435 | F13: ='[1]kışlık desen'!F13 -> 50 | G13: =F13/C36 -> 1.2658228 | H13: =D13/G41 -> 250 | I13: =C13/G41 -> 139.17825 | J13: =H13-I13 -> 110.82175
A14: Aralık | B14: =H76*B35 -> 20000 | C14: =J32 -> 2029940.2 | D14: =B14*F14 -> 1000000 | E14: =D14-C14 -> -1029940.2 | F14: ='[1]kışlık desen'!F14 -> 50 | G14: =F14/C36 -> 1.2658228 | H14: =D14/G41 -> 50 | I14: =C14/G41 -> 101.49701 | J14: =H14-I14 -> -51.49701
A15: TOPLAM | B15: =SUM(B3:B14) -> 900000 | C15: =SUM(C3:C14) -> 17882567 | D15: =SUM(D3:D14) -> 27900000 | E15: =SUM(E3:E14) -> 10017433 | F15: =D15/B15 -> 31 | G15: =F15/C36 -> 0.78481013 | H15: =D15/G41 -> 1395 | I15: =C15/G41 -> 894.12833 | J15: =H15-I15 -> 500.87167
A16: usd/m2 | C16: =C15/C36 -> 452723.21 | D16: =D15/C36 -> 706329.11 | E16: =E15/C36 -> 253605.91 | H16: =D16/B35 -> 35.316456 | I16: =C16/B35 -> 22.63616 | J16: =H16-I16 -> 12.680295
A19: AYLAR | B19: HAMMADDE GİDERLERİ (TL) | F19: ENERJİ GİDERLERİ (TL) | G19: PERSONEL GİDERLERİ (TL) | H19: AMBALAJ GİDERLERİ (TL) | I19: G.Ü.G (TL) | J19: TOPLAM GİDER (TL)
B20: GÜBRE | C20: TOHUM/FİDE | D20: ÜRETİM ORTAMI | E20: İLAÇ
A21: OCAK | B21: =D104*B35 -> 0 | E21: 0 | F21: =(B35*B47*5)+D47*B35 -> 260000 | G21: =H88+I88 -> 74246.2 | H21: =C62*B35 -> 0 | I21: 0 | J21: =SUM(B21:I21) -> 334246.2
A22: ŞUBAT | B22: =D105*B35 -> 0 | F22: =B35*B48*5+D48*B35 -> 260000 | G22: =H89+I89 -> 74246.2 | H22: =C63*B35 -> 0 | I22: 0 | J22: =SUM(B22:I22) -> 334246.2
A23: MART | B23: =D106*B35 -> 13740 | E23: =B35*(B38/4)*C36 -> 98750 | F23: =B35*B49*5+D49*B35 -> 672857.14 | G23: =H90+I90 -> 371214.2 | H23: =C64*B35 -> 0 | I23: =(E127+F127+H127+K127+G49+J49)/20000*B35 -> 79987.97 | J23: =SUM(B23:I23) -> 1236549.3
A24: NİSAN | B24: =D107*B35 -> 68700 | E24: =E23 -> 98750 | F24: =B35*B50*5+D50*B35 -> 417142.86 | G24: =H91+I91 -> 371214.2 | H24: =C65*B35 -> 0 | I24: =(E128+F128+H128+K128+G50+J50)/20000*B35 -> 49628.95 | J24: =SUM(B24:I24) -> 1005436
A25: MAYIS | B25: =D108*B35 -> 137400 | E25: =E21 -> 0 | F25: =B35*B51*5+D51*B35 -> 170771.43 | G25: =H92+I92 -> 742424.2 | H25: =C66*B35 -> 60000 | I25: =(E129+F129+H129+K129+G51+J51)/15000*B35 -> 156190.11 | J25: =SUM(B25:I25) -> 1266785.7
A26: HAZİRAN | B26: =D109*B35 -> 206100 | F26: =B35*B52*5+D52*B35 -> 53214.286 | G26: =H93+I93 -> 890908.2 | H26: =C67*B35 -> 360000 | I26: =(E130+F130+H130+K130+G52+J52)/15000*B35 -> 104276 | J26: =SUM(B26:I26) -> 1614498.5
A27: TEMMUZ | B27: =D110*B35 -> 412200 | E27: =E23 -> 98750 | F27: =B35*B53*5+D53*B35 -> 52914.286 | G27: =H94+I94 -> 890908.2 | H27: =C68*B35 -> 600000 | I27: =(E131+F131+H131+K131+G53+J53)/20000*B35 -> 278007.28 | J27: =SUM(B27:I27) -> 2332779.8
A28: AĞUSTOS | B28: =D111*B35 -> 412200 | F28: =B35*B54*5+D54*B35 -> 50000 | G28: =H95+I95 -> 890908.2 | H28: =C69*B35 -> 600000 | I28: =(E132+F132+H132+K132+G54+J54)/15000*B35 -> 153617.33 | J28: =SUM(B28:I28) -> 2106725.5
A29: EYLÜL | B29: =D112*B35 -> 137400 | E29: =E23 -> 98750 | F29: =B35*B55*5+D55*B35 -> 65114.286 | G29: =H96+I96 -> 742424.2 | H29: =C70*B35 -> 360000 | I29: =(E133+F133+H133+K133+G55+J55)/20000*B35 -> 33603 | J29: =SUM(B29:I29) -> 1437291.5
A30: EKİM | B30: =D113*B35 -> 68700 | F30: =B35*B56*5+D56*B35 -> 182857.14 | G30: =H97+I97 -> 742424.2 | H30: =C71*B35 -> 360000 | I30: =(E134+F134+H134+K134+G56+J56)/20000*B35 -> 46521.33 | J30: =SUM(B30:I30) -> 1400502.7
A31: KASIM | B31: =D114*B35 -> 41220 | C31: =B35*3.6*8 -> 576000 | D31: =B35*C39*C36*0.6 -> 711000 | F31: =B35*B57*5+D57*B35 -> 545000 | G31: =H98+I98 -> 593940.2 | H31: =C72*B35 -> 300000 | I31: =(E135+F135+H135+K135+G57+J57)/20000*B35 -> 16404.84 | J31: =SUM(B31:I31) -> 2783565
A32: ARALIK* | B32: =D115*B35 -> 0 | C32: =B35*3.6*8 -> 576000 | F32: =B35*B58*5+D58*B35 -> 800000 | G32: =H99+I99 -> 593940.2 | H32: =C73*B35 -> 60000 | I32: =(E136+F136+H136+K136+G58+J58)/20000*B35 -> 0 | J32: =SUM(B32:I32) -> 2029940.2
A33: TOPLAM | B33: =SUM(B21:B32) -> 1497660 | C33: =SUM(C21:C32) -> 1152000 | D33: =SUM(D21:D32) -> 711000 | E33: =SUM(E21:E32) -> 395000 | F33: =SUM(F21:F32) -> 3529871.4 | G33: =SUM(G21:G32) -> 6978798.4 | H33: =SUM(H21:H32) -> 2700000 | I33: =SUM(I21:I32) -> 918236.81 | J33: =SUM(B33:I33) -> 17882567
A34: toplam usd/m2 | B34: =B33/C36 -> 37915.443 | C34: =C33/C36 -> 29164.557 | D34: =D33/C36 -> 18000 | E34: =E33/C36 -> 10000 | F34: =F33/C36 -> 89363.834 | G34: =G33/C36 -> 176678.44 | H34: =H33/C36 -> 68354.43 | I34: =I33/C36 -> 23246.502 | J34: =J33/C36 -> 452723.21
A35: sera alanı m2 | B35: 20000
A36: usd/tl | C36: 39.5
A37: Gübre | B37: =B33/B35 -> 74.883
A38: İlaç | B38: 0.5 | C38: usd/m2 | D38: 0.25 | E38: usd/m2 | F38: toplam ilaç | G38: =B38+D38+J38 -> 1.01 | H38: usd/m2 | I38: stopmate usd/m2 | J38: 0.26
A39: Üretim ort. Cocopeat | C39: 1.5 | D39: usd/adet
A40: tohum/fide | B40: 3.6 | C40: bitki/m2
A41: işçilik | B41: =J86 -> 445.452 | C41: tl/m2 | E41: sera alanı m2 | G41: =B35 -> 20000
A42: elektrik/doğalgaz | B42: ='[2]yazlık sera girdi maliyeti'!$D$9 -> 46.5 | C42: tl/m2
...

Sheet yat.geri dönüş
A1: TOPRAKSIZ TARIM YÖNTEMİYLE SERADA SALKIM DOMATES ÜRETİMİNE İLİŞKİN 5 YILLIK GELİR / GİDER İCMAL TABLOSU yazlık üretim deseni | J1: anahtar teslim sera usd/m2
A2: AYLAR | B2: AYLIK ÜRETİM MİKTARI (kg) | C2: DOMATES SATIŞ FİYATLARI usd/kg | D2: 1. YIL HASILAT usd | E2: 2. YIL HASILAT usd | F2: 3. YIL HASILAT usd | G2: 4. YIL HASILAT usd | H2: 5. YIL HASILAT usd | I2: TOPLAM GELİR usd | J2: plastik | K2: Cam
J3: 80 | K3: 0
A4: Ocak | B4: =yazlık!B3 -> 0 | C4: =yazlık!G3 -> 1.3924051 | D4: =B4*C4 -> 0 | E4: =B4*C4 -> 0 | F4: =B4*C4 -> 0 | G4: =B4*C4 -> 0 | H4: =B4*C4 -> 0 | I4: =SUM(D4:H4) -> 0
A5: Şubat | B5: =yazlık!B4 -> 0 | C5: =yazlık!G4 -> 1.3924051 | D5: =B5*C5 -> 0 | E5: =B5*C5 -> 0 | F5: =B5*C5 -> 0 | G5: =B5*C5 -> 0 | H5: =B5*C5 -> 0 | I5: =SUM(D5:H5) -> 0
A6: Mart | B6: =yazlık!B5 -> 20000 | C6: =yazlık!G5 -> 1.3924051 | D6: =B6*C6 -> 27848.101 | E6: =B6*C6 -> 27848.101 | F6: =B6*C6 -> 27848.101 | G6: =B6*C6 -> 27848.101 | H6: =B6*C6 -> 27848.101 | I6: =SUM(D6:H6) -> 139240.51
A7: Nisan | B7: =yazlık!B6 -> 80000 | C7: =yazlık!G6 -> 1.2658228 | D7: =B7*C7 -> 101265.82 | E7: =B7*C7 -> 101265.82 | F7: =B7*C7 -> 101265.82 | G7: =B7*C7 -> 101265.82 | H7: =B7*C7 -> 101265.82 | I7: =SUM(D7:H7) -> 506329.11
A8: Mayıs | B8: =yazlık!B7 -> 120000 | C8: =yazlık!G7 -> 0.63291139 | D8: =B8*C8 -> 75949.367 | E8: =B8*C8 -> 75949.367 | F8: =B8*C8 -> 75949.367 | G8: =B8*C8 -> 75949.367 | H8: =B8*C8 -> 75949.367 | I8: =SUM(D8:H8) -> 379746.84
A9: Haziran | B9: =yazlık!B8 -> 180000 | C9: =yazlık!G8 -> 0.63291139 | D9: =B9*C9 -> 113924.05 | E9: =B9*C9 -> 113924.05 | F9: =B9*C9 -> 113924.05 | G9: =B9*C9 -> 113924.05 | H9: =B9*C9 -> 113924.05 | I9: =SUM(D9:H9) -> 569620.25
A10: Temmuz | B10: =yazlık!B9 -> 220000 | C10: =yazlık!G9 -> 0.63291139 | D10: =B10*C10 -> 139240.51 | E10: =B10*C10 -> 139240.51 | F10: =B10*C10 -> 139240.51 | G10: =B10*C10 -> 139240.51 | H10: =B10*C10 -> 139240.51 | I10: =SUM(D10:H10) -> 696202.53
A11: Ağustos | B11: =yazlık!B10 -> 220000 | C11: =yazlık!G10 -> 0.63291139 | D11: =B11*C11 -> 139240.51 | E11: =B11*C11 -> 139240.51 | F11: =B11*C11 -> 139240.51 | G11: =B11*C11 -> 139240.51 | H11: =B11*C11 -> 139240.51 | I11: =SUM(D11:H11) -> 696202.53
A12: Eylül | B12: =yazlık!B11 -> 120000 | C12: =yazlık!G11 -> 0.75949367 | D12: =B12*C12 -> 91139.241 | E12: =B12*C12 -> 91139.241 | F12: =B12*C12 -> 91139.241 | G12: =B12*C12 -> 91139.241 | H12: =B12*C12 -> 91139.241 | I12: =SUM(D12:H12) -> 455696.2
A13: Ekim | B13: =yazlık!B12 -> 100000 | C13: =yazlık!G12 -> 0.88607595 | D13: =B13*C13 -> 88607.595 | E13: =B13*C13 -> 88607.595 | F13: =B13*C13 -> 88607.595 | G13: =B13*C13 -> 88607.595 | H13: =B13*C13 -> 88607.595 | I13: =SUM(D13:H13) -> 443037.97
A14: Kasım | B14: =yazlık!B13 -> 80000 | C14: =yazlık!G13 -> 1.0126582 | D14: =B14*C14 -> 81012.658 | E14: =B14*C14 -> 81012.658 | F14: =B14*C14 -> 81012.658 | G14: =B14*C14 -> 81012.658 | H14: =B14*C14 -> 81012.658 | I14: =SUM(D14:H14) -> 405063.29
A15: Aralık | B15: =yazlık!B14 -> 0 | C15: =yazlık!G14 -> 1.2658228 | D15: =B15*C15 -> 0 | E15: =B15*C15 -> 0 | F15: =B15*C15 -> 0 | G15: =B15*C15 -> 0 | H15: =B15*C15 -> 0 | I15: =SUM(D15:H15) -> 0
A16: TOPLAM | B16: =SUM(B4:B15) -> 1140000 | C16: =D17/B16 -> 0.75283145
A17: Hasılat Toplamı | D17: =SUM(D4:D15) -> 858227.85 | E17: =SUM(E4:E15) -> 858227.85 | F17: =SUM(F4:F15) -> 858227.85 | G17: =SUM(G4:G15) -> 858227.85 | H17: =SUM(H4:H15) -> 858227.85 | I17: =SUM(D17:H17) -> 4291139.2
A18: İşletme Giderleri | D18: =yazlık!J34 -> 551756.22 | E18: =D18 -> 551756.22 | F18: =D18 -> 551756.22 | G18: =D18 -> 551756.22 | H18: =D18 -> 551756.22 | I18: =SUM(D18:H18) -> 2758781.1 | J18: =J3*yazlık!B35 -> 1600000 | K18: =K3*yazlık!B35 -> 0
A19: kar/zarar | D19: =D17-D18 -> 306471.63 | E19: =E17-E18 -> 306471.63 | F19: =F17-F18 -> 306471.63 | G19: =G17-G18 -> 306471.63 | H19: =H17-H18 -> 306471.63 | I19: =SUM(D19:H19) -> 1532358.1 | J19: =J18/D19 -> 5.2207116 | K19: =K18/D19 -> 0 | L19: yıl
